======================================================================
ERROR: A gff-file to gffutils-database converter ( gff_to_db.py ) > Test-1
----------------------------------------------------------------------
Traceback (most recent call last):
  File "/home/sidhe/galaxy/test/functional/test_toolbox.py", line 270, in test_tool
    self.do_it( td )
  File "/home/sidhe/galaxy/test/functional/test_toolbox.py", line 37, in do_it
    stage_data_in_history( galaxy_interactor, testdef.test_data(), test_history, shed_tool_id )
  File "/home/sidhe/galaxy/test/base/interactor.py", line 42, in stage_data_in_history
    upload_wait()
  File "/home/sidhe/galaxy/test/base/interactor.py", line 279, in wait
    while not self.__history_ready( history_id ):
  File "/home/sidhe/galaxy/test/base/interactor.py", line 297, in __history_ready
    return self._state_ready( state, error_msg="History in error state." )
  File "/home/sidhe/galaxy/test/base/interactor.py", line 356, in _state_ready
    raise Exception( error_msg )
Exception: History in error state.
-------------------- >> begin captured stdout << ---------------------
History with id 2891970512fa2d5a in error - summary of datasets in error below.
--------------------------------------
| 1 - FlyBase.gff (HID - NAME) 
| Dataset Blurb:
|  error
| Dataset Info:
|  uploaded gff file
|  /usr/lib/python2.7/dist-packages/pkg_resources.py:1031: UserWarning: /home/sidhe/.python-eggs is writable by group/others and vulnerable to attack when used with get_resource_filename. Consider a more secure location (set with .set_extr
| Dataset Job Standard Output:
|  *Standard output was empty.*
| Dataset Job Standard Error:
|  /usr/lib/python2.7/dist-packages/pkg_resources.py:1031: UserWarning: /home/sidhe/.python-eggs is writable by group/others and vulnerable to attack when used with get_resource_filename. Consider a more secure location (set with .set_extraction_path or the PYTHON_EGG_CACHE environment variable).
|  warnings.warn(msg, UserWarning)
|
--------------------------------------

--------------------- >> end captured stdout << ----------------------
-------------------- >> begin captured logging << --------------------

There were problems with 1 test(s) - out of 1 test(s) executed. See /media/sf_work/anotation_db/tool_test_output.html for detailed breakdown.
gff_to_db.py[0]: failed
